<mujoco model="base">
  <compiler angle="radian" meshdir="meshes/" inertiagrouprange="0 0" />
  <option impratio="20" cone="elliptic" density="1.2" viscosity="0.00002" timestep="0.002" />
  <size nconmax="5000" njmax="5000" />

  <asset>
  <texture builtin="gradient" height="256" rgb1=".9 .9 1." rgb2=".2 .3 .4" type="skybox" width="256" />
    <texture file="/home/litao/Downloads/robotic-ultrasound-imaging-master/src/my_models/assets/arenas/../textures/hospital_floor.png" type="2d" name="texplane" />
    <material name="floorplane" reflectance="0.01" shininess="0.0" specular="0.0" texrepeat="2 2" texture="texplane" texuniform="true" />
    
    <texture file="/home/litao/Downloads/robotic-ultrasound-imaging-master/src/my_models/assets/arenas/../textures/ceramic.png" type="cube" name="tex-ceramic" />
    <material name="table_ceramic" reflectance="0.0" shininess="0.0" specular="0.2" texrepeat="1 1" texture="tex-ceramic" />
    
    <texture file="/home/litao/Downloads/robotic-ultrasound-imaging-master/src/my_models/assets/arenas/../textures/steel-brushed.png" type="cube" name="tex-steel-brushed" />
    <material name="table_legs_metal" reflectance="0.8" shininess="0.8" texrepeat="1 1" texture="tex-steel-brushed" />
    
    <texture file="/home/litao/Downloads/robotic-ultrasound-imaging-master/src/my_models/assets/arenas/../textures/hospital_wall.png" type="2d" name="tex-hospital-wall" />
    <material name="walls_mat" reflectance="0.0" shininess="0.1" specular="0.1" texrepeat="1 1" texture="tex-hospital-wall" texuniform="false" />
    
    <texture name="textable" builtin="flat" height="512" width="512" rgb1="0.5 0.5 0.5" rgb2="0.5 0.5 0.5" />
    <material name="table_mat" texture="textable" />

  <mesh name="robot0_link0" file="/home/litao/miniconda3/envs/rl_ultrasound/lib/python3.8/site-packages/robosuite/models/assets/robots/panda/meshes/link0.stl" />
        <mesh name="robot0_link1" file="/home/litao/miniconda3/envs/rl_ultrasound/lib/python3.8/site-packages/robosuite/models/assets/robots/panda/meshes/link1.stl" />
        <mesh name="robot0_link2" file="/home/litao/miniconda3/envs/rl_ultrasound/lib/python3.8/site-packages/robosuite/models/assets/robots/panda/meshes/link2.stl" />
        <mesh name="robot0_link3" file="/home/litao/miniconda3/envs/rl_ultrasound/lib/python3.8/site-packages/robosuite/models/assets/robots/panda/meshes/link3.stl" />
        <mesh name="robot0_link4" file="/home/litao/miniconda3/envs/rl_ultrasound/lib/python3.8/site-packages/robosuite/models/assets/robots/panda/meshes/link4.stl" />
        <mesh name="robot0_link5" file="/home/litao/miniconda3/envs/rl_ultrasound/lib/python3.8/site-packages/robosuite/models/assets/robots/panda/meshes/link5.stl" />
        <mesh name="robot0_link6" file="/home/litao/miniconda3/envs/rl_ultrasound/lib/python3.8/site-packages/robosuite/models/assets/robots/panda/meshes/link6.stl" />
        <mesh name="robot0_link7" file="/home/litao/miniconda3/envs/rl_ultrasound/lib/python3.8/site-packages/robosuite/models/assets/robots/panda/meshes/link7.stl" />
        <mesh name="robot0_link0_vis" file="/home/litao/miniconda3/envs/rl_ultrasound/lib/python3.8/site-packages/robosuite/models/assets/robots/panda/meshes/link0_vis.stl" />
        <mesh name="robot0_link1_vis" file="/home/litao/miniconda3/envs/rl_ultrasound/lib/python3.8/site-packages/robosuite/models/assets/robots/panda/meshes/link1_vis.stl" />
        <mesh name="robot0_link2_vis" file="/home/litao/miniconda3/envs/rl_ultrasound/lib/python3.8/site-packages/robosuite/models/assets/robots/panda/meshes/link2_vis.stl" />
        <mesh name="robot0_link3_vis" file="/home/litao/miniconda3/envs/rl_ultrasound/lib/python3.8/site-packages/robosuite/models/assets/robots/panda/meshes/link3_vis.stl" />
        <mesh name="robot0_link4_vis" file="/home/litao/miniconda3/envs/rl_ultrasound/lib/python3.8/site-packages/robosuite/models/assets/robots/panda/meshes/link4_vis.stl" />
        <mesh name="robot0_link5_vis" file="/home/litao/miniconda3/envs/rl_ultrasound/lib/python3.8/site-packages/robosuite/models/assets/robots/panda/meshes/link5_vis.stl" />
        <mesh name="robot0_link6_vis" file="/home/litao/miniconda3/envs/rl_ultrasound/lib/python3.8/site-packages/robosuite/models/assets/robots/panda/meshes/link6_vis.stl" />
        <mesh name="robot0_link7_vis" file="/home/litao/miniconda3/envs/rl_ultrasound/lib/python3.8/site-packages/robosuite/models/assets/robots/panda/meshes/link7_vis.stl" />
    <mesh name="mount0_pedestal" file="/home/litao/miniconda3/envs/rl_ultrasound/lib/python3.8/site-packages/robosuite/models/assets/mounts/meshes/rethink_mount/pedestal.stl" />
    <mesh file="/home/litao/Downloads/robotic-ultrasound-imaging-master/src/my_models/assets/grippers/meshes/ultrasound_probe_mesh.stl" name="gripper0_probe_mesh" scale="0.001 0.001 0.001" />
  <texture file="/home/litao/Downloads/robotic-ultrasound-imaging-master/src/my_models/assets/objects/../textures/skin.png" type="2d" name="torso_skin-tex" />
    <material name="torso_skin-material" reflectance="0.5" texrepeat="1 1" texture="torso_skin-tex" />
  </asset>

  <visual>
    <map znear="0.001" />
  </visual>

  <actuator>
  <motor ctrllimited="true" ctrlrange="-80.0 80.0" joint="robot0_joint1" name="robot0_torq_j1" />
        <motor ctrllimited="true" ctrlrange="-80.0 80.0" joint="robot0_joint2" name="robot0_torq_j2" />
        <motor ctrllimited="true" ctrlrange="-80.0 80.0" joint="robot0_joint3" name="robot0_torq_j3" />
        <motor ctrllimited="true" ctrlrange="-80.0 80.0" joint="robot0_joint4" name="robot0_torq_j4" />
        <motor ctrllimited="true" ctrlrange="-80.0 80.0" joint="robot0_joint5" name="robot0_torq_j5" />
        <motor ctrllimited="true" ctrlrange="-12.0 12.0" joint="robot0_joint6" name="robot0_torq_j6" />
        <motor ctrllimited="true" ctrlrange="-12.0 12.0" joint="robot0_joint7" name="robot0_torq_j7" />
    </actuator>

  <worldbody>
  <geom condim="3" material="floorplane" name="floor" pos="0.0 0.0 0.0" size="3 3 .125" type="plane" />
    
    <geom pos="-1.25 2.25 1.5" quat="0.6532815 0.6532815 0.2705981 0.2705981" size="1.06 1.5 0.01" type="box" conaffinity="0" contype="0" group="1" name="wall_leftcorner_visual" material="walls_mat" />
    <geom pos="-1.25 -2.25 1.5" quat="0.6532815 0.6532815 -0.2705981 -0.2705981" size="1.06 1.5 0.01" type="box" conaffinity="0" contype="0" group="1" name="wall_rightcorner_visual" material="walls_mat" />
    <geom pos="1.25 3.0 1.5" quat="0.7071 0.7071 0 0" size="1.75 1.5 0.01" type="box" conaffinity="0" contype="0" group="1" name="wall_left_visual" material="walls_mat" />
    <geom pos="1.25 -3.0 1.5" quat="-0.7071 -0.7071 0 0" size="1.75 1.5 0.01" type="box" conaffinity="0" contype="0" group="1" name="wall_right_visual" material="walls_mat" />
    <geom pos="-2.0 0.0 1.5" quat="0.5 0.5 0.5 0.5" size="1.5 1.5 0.01" type="box" conaffinity="0" contype="0" group="1" name="wall_rear_visual" material="walls_mat" />
    <geom pos="3.0 0.0 1.5" quat="0.5 0.5 -0.5 -0.5" size="3 1.5 0.01" type="box" conaffinity="0" contype="0" group="1" name="wall_front_visual" material="walls_mat" />
    
    <body name="table" pos="0.0 0.0 0.775">
      <geom pos="0 0 0" size="0.4 0.4 0.025" type="box" name="table_collision" friction="1 0.005 0.0001" rgba="0.5 0.5 0 1" />
      <geom pos="0 0 0" size="0.4 0.4 0.025" type="box" conaffinity="0" contype="0" group="1" name="table_visual" material="table_ceramic" />
      <site pos="0.0 0.0 0.025" name="table_top" size="0.001 0.001 0.001" rgba="0 0 0 0" />
      
      <geom pos="0.30000000000000004 0.30000000000000004 -0.3875" size="0.025 0.3875" type="cylinder" conaffinity="0" contype="0" group="1" name="table_leg1_visual" material="table_legs_metal" />
      <geom pos="-0.30000000000000004 0.30000000000000004 -0.3875" size="0.025 0.3875" type="cylinder" conaffinity="0" contype="0" group="1" name="table_leg2_visual" material="table_legs_metal" />
      <geom pos="-0.30000000000000004 -0.30000000000000004 -0.3875" size="0.025 0.3875" type="cylinder" conaffinity="0" contype="0" group="1" name="table_leg3_visual" material="table_legs_metal" />
      <geom pos="0.30000000000000004 -0.30000000000000004 -0.3875" size="0.025 0.3875" type="cylinder" conaffinity="0" contype="0" group="1" name="table_leg4_visual" material="table_legs_metal" />
    </body>

    <light name="light1" diffuse=".8 .8 .8" dir="0 -.15 -1" directional="false" pos="1.0 1.0 4.0" specular="0.3 0.3 0.3" castshadow="false" />
    <light name="light2" diffuse=".8 .8 .8" dir="0 -.15 -1" directional="false" pos="-3.0 -3.0 4.0" specular="0.3 0.3 0.3" castshadow="false" />
    
    <camera mode="fixed" name="frontview" pos="1.6 0.0 1.45" quat="0.56 0.43 0.43 0.56" />
    
    <camera mode="fixed" name="birdview" pos="-0.2 0.0 3.0" quat="0.7071 0 0 0.7071" />
    
    <camera mode="fixed" name="agentview" pos="0.5 0.0 1.35" quat="0.653 0.271 0.271 0.653" />
    
    <camera mode="fixed" name="sideview" pos="-0.05651774593317116 1.2761224129427358 1.4879572214102434" quat="0.009905065491771751 0.006877963156909582 0.5912228352893879 0.806418094001364" />
  <body name="robot0_base" pos="-0.56 0.0 0.912">
            
            <camera mode="fixed" name="robot0_robotview" pos="1.0 0 0.4" quat="0.653 0.271 0.271 0.653" />
            <inertial diaginertia="0 0 0" mass="0" pos="0 0 0" />
            
            <body name="robot0_link0" pos="0 0 0">
                <inertial pos="0 0 0.05" mass="4" diaginertia="0.4 0.4 0.4" />
                <geom type="mesh" contype="0" conaffinity="0" group="1" mesh="robot0_link0_vis" name="robot0_link0_visual" rgba="1 1 1 1" />
                <geom type="mesh" group="0" mesh="robot0_link0" name="robot0_link0_collision" rgba="0 0.5 0 1" />
                <body name="robot0_link1" pos="0 0 0.333">
                    <inertial pos="0 0 -0.07" mass="3" diaginertia="0.3 0.3 0.3" />
                    <joint name="robot0_joint1" pos="0 0 0" axis="0 0 1" limited="true" range="-2.8973 2.8973" damping="0.1" frictionloss="0.1" armature="5.0" />
                    <geom type="mesh" contype="0" conaffinity="0" group="1" mesh="robot0_link1_vis" name="robot0_link1_visual" rgba="1 1 1 1" />
                    <geom type="mesh" group="0" mesh="robot0_link1" name="robot0_link1_collision" rgba="0 0.5 0 1" />
                    <body name="robot0_link2" pos="0 0 0" quat="0.707107 -0.707107 0 0">
                        <inertial pos="0 -0.1 0" mass="3" diaginertia="0.3 0.3 0.3" />
                        <joint name="robot0_joint2" pos="0 0 0" axis="0 0 1" limited="true" range="-1.7628 1.7628" damping="0.1" frictionloss="0.1" armature="2.5" />
                        <geom type="mesh" contype="0" conaffinity="0" group="1" mesh="robot0_link2_vis" name="robot0_link2_visual" rgba="1 1 1 1" />
                        <geom type="mesh" group="0" mesh="robot0_link2" name="robot0_link2_collision" rgba="0 0.5 0 1" />
                        <body name="robot0_link3" pos="0 -0.316 0" quat="0.707107 0.707107 0 0">
                            <inertial pos="0.04 0 -0.05" mass="2" diaginertia="0.2 0.2 0.2" />
                            <joint name="robot0_joint3" pos="0 0 0" axis="0 0 1" limited="true" range="-2.8973 2.8973" damping="0.1" frictionloss="0.1" armature="1.6666666666666667" />
                            <geom type="mesh" contype="0" conaffinity="0" group="1" mesh="robot0_link3_vis" name="robot0_link3_visual" rgba="1 1 1 1" />
                            <geom type="mesh" group="0" mesh="robot0_link3" name="robot0_link3_collision" rgba="0 0.5 0 1" />
                            <body name="robot0_link4" pos="0.0825 0 0" quat="0.707107 0.707107 0 0">
                                <inertial pos="-0.04 0.05 0" mass="2" diaginertia="0.2 0.2 0.2" />
                                <joint name="robot0_joint4" pos="0 0 0" axis="0 0 1" limited="true" range="-3.0718 -0.0698" damping="0.1" frictionloss="0.1" armature="1.25" />
                                <geom type="mesh" contype="0" conaffinity="0" group="1" mesh="robot0_link4_vis" name="robot0_link4_visual" rgba="1 1 1 1" />
                                <geom type="mesh" group="0" mesh="robot0_link4" name="robot0_link4_collision" rgba="0 0.5 0 1" />
                                <body name="robot0_link5" pos="-0.0825 0.384 0" quat="0.707107 -0.707107 0 0">
                                    <inertial pos="0 0 -0.15" mass="2" diaginertia="0.2 0.2 0.2" />
                                    <joint name="robot0_joint5" pos="0 0 0" axis="0 0 1" limited="true" range="-2.8973 2.8973" damping="0.1" frictionloss="0.1" armature="1.0" />
                                    <geom type="mesh" contype="0" conaffinity="0" group="1" mesh="robot0_link5_vis" name="robot0_link5_visual" rgba="1 1 1 1" />
                                    <geom type="mesh" group="0" mesh="robot0_link5" name="robot0_link5_collision" rgba="0 0.5 0 1" />
                                    <body name="robot0_link6" pos="0 0 0" quat="0.707107 0.707107 0 0">
                                        <inertial pos="0.06 0 0" mass="1.5" diaginertia="0.1 0.1 0.1" />
                                        <joint name="robot0_joint6" pos="0 0 0" axis="0 0 1" limited="true" range="-0.0175 3.7525" damping="0.01" frictionloss="0.1" armature="0.8333333333333334" />
                                        <geom type="mesh" contype="0" conaffinity="0" group="1" mesh="robot0_link6_vis" name="robot0_link6_visual" rgba="1 1 1 1" />
                                        <geom type="mesh" group="0" mesh="robot0_link6" name="robot0_link6_collision" rgba="0 0.5 0 1" />
                                        <body name="robot0_link7" pos="0.088 0 0" quat="0.707107 0.707107 0 0">
                                            <inertial pos="0 0 0.08" mass="0.5" diaginertia="0.05 0.05 0.05" />
                                            <joint name="robot0_joint7" pos="0 0 0" axis="0 0 1" limited="true" range="-2.8973 2.8973" damping="0.01" frictionloss="0.1" armature="0.7142857142857143" />
                                            <geom type="mesh" contype="0" conaffinity="0" group="1" mesh="robot0_link7_vis" name="robot0_link7_visual" rgba="1. 1. 1. 1." />
                                            <geom type="mesh" group="0" mesh="robot0_link7" name="robot0_link7_collision" rgba="0 0.5 0 1" />
                                            
                                            <body name="robot0_right_hand" pos="0 0 0.1065" quat="0.924 0 0 -0.383">
                                                <inertial pos="0 0 0" mass="0.5" diaginertia="0.05 0.05 0.05" />
                                                
                                                <camera mode="fixed" name="robot0_eye_in_hand" pos="0.05 0 0" quat="0 0.707108 0.707108 0" fovy="75" />
                                                
                                            <body name="gripper0_gripper_base" pos="-0.004 -0.063 0.128" quat="1 0 0 0">
        <site name="gripper0_ft_frame" size="0.01 0.01 0.01" rgba="1 0 0 1" type="sphere" group="1" /> 
        <geom name="gripper0_probe_collision" mesh="gripper0_probe_mesh" type="mesh" mass="1" friction="0.0001 0.005 0.0001" group="0" rgba="0 0 0.5 1" />
        <geom name="gripper0_probe_visual" mesh="gripper0_probe_mesh" type="mesh" group="1" />
        
        <site name="gripper0_grip_site" size="0.01 0.01 0.01" rgba="1 0 0 0.5" type="sphere" group="1" />
        <site name="gripper0_grip_site_cylinder" size="0.005 0.01" rgba="0 1 0 0.3" type="cylinder" group="1" />
    </body>
  </body>
                                        </body>
                                    </body>
                                </body>
                            </body>
                        </body>
                    </body>
                </body>
            </body>
        <body name="mount0_base" pos="0.0 0.0 0.01">
            <body name="mount0_controller_box" pos="0 0 0">
                <inertial diaginertia="1.71363 1.27988 0.809981" mass="46.64" pos="-0.325 0 -0.38" />
                <geom pos="-0.325 0 -0.38" size="0.11 0.2 0.265" type="box" name="mount0_controller_box_col" rgba="0.5 0.5 0 1" />
            </body>
            <body name="mount0_pedestal_feet" pos="0 0 0">
                <inertial diaginertia="8.16095 9.59375 15.0785" mass="167.09" pos="-0.1225 0 -0.758" />
                <geom pos="-0.1225 0 -0.758" size="0.385 0.35 0.155" type="box" name="mount0_pedestal_feet_col" rgba="0.5 0.5 0 1" />
            </body>
            <body name="mount0_torso" pos="0 0 0">
                <inertial diaginertia="1e-08 1e-08 1e-08" mass="0.0001" pos="0 0 0" />
                <geom conaffinity="0" contype="0" group="1" pos="0 0 -0.05" size="0.05 0.05 0.05" type="box" name="mount0_torso_vis" rgba="0.2 0.2 0.2 1" />
            </body>
            <body name="mount0_pedestal" pos="0 0 0">
                <inertial diaginertia="6.0869 5.81635 4.20915" mass="60.864" pos="0 0 0" quat="0.659267 -0.259505 -0.260945 0.655692" />
                <geom conaffinity="0" contype="0" group="1" mesh="mount0_pedestal" type="mesh" name="mount0_pedestal_vis" rgba="0.2 0.2 0.2 1" />
                <geom pos="-0.02 0 -0.29" rgba="0.5 0.5 0 1" size="0.18 0.31" type="cylinder" name="mount0_pedestal_col" />
            </body>
        </body>
    </body>
    <body name="torso_main" pos="0.5 0.5 0.06" quat="0.5 0.5 -0.5 -0.5">
        <composite type="box" count="9 4 11" spacing="0.035"  solrefsmooth="-1324.17 -17.59">
            <geom type="capsule" size="0.0075 0.025" rgba=".8 .2 .1 1" mass="0.01" friction="0.01 0.005 0.0001" contype="0" group="0" />  
            <skin material="torso_skin-material" texcoord="true" />
        </composite>
        <joint type="free" name="torso_joint0" /><site pos="0 0 0" size="0.002 0.002 0.002" rgba="1 0 0 0" type="sphere" group="0" name="torso_default_site" />
    </body>
</worldbody>

  <equality>
  </equality>
<sensor><force name="gripper0_force_ee" site="gripper0_ft_frame" />
        <torque name="gripper0_torque_ee" site="gripper0_ft_frame" />
    </sensor><tendon /><contact /><default /></mujoco>
